<!doctype html><html lang=cn><head><meta charset=utf-8><meta http-equiv=x-ua-compatible content="IE=edge"><meta name=viewport content="width=device-width,initial-scale=1"><meta name=referrer content="no-referrer"><link rel=dns-prefetch href=https://i.geekbank.cf/><title>Python异常处理（二十六） | 极客快訊</title><meta property="og:title" content="Python异常处理（二十六） - 极客快訊"><meta property="og:type" content="article"><meta property="og:locale" content="cn"><meta property="og:image" content="https://p1.pstatp.com/large/pgc-image/b042ebd0bbf644a2b82bf1b115e79517"><link rel=alternate hreflang=x-default href=https://geekbank.cf/tw/%e7%a7%91%e6%8a%80/b290700d.html><link rel=alternate hreflang=zh-tw href=https://geekbank.cf/tw/%e7%a7%91%e6%8a%80/b290700d.html><link rel=alternate hreflang=zh-cn href=https://geekbank.cf/cn/%e7%a7%91%e6%8a%80/b290700d.html><link rel=alternate hreflang=zh-hk href=https://geekbank.cf/tw/%e7%a7%91%e6%8a%80/b290700d.html><link rel=alternate hreflang=zh-mo href=https://geekbank.cf/tw/%e7%a7%91%e6%8a%80/b290700d.html><link rel=alternate hreflang=zh-my href=https://geekbank.cf/cn/%e7%a7%91%e6%8a%80/b290700d.html><link rel=alternate hreflang=zh-sg href=https://geekbank.cf/cn/%e7%a7%91%e6%8a%80/b290700d.html><link rel=canonical href=https://geekbank.cf/tw/%e7%a7%91%e6%8a%80/b290700d.html><meta property="article:published_time" content="2020-11-14T21:03:15+08:00"><meta property="article:modified_time" content="2020-11-14T21:03:15+08:00"><meta name=Keywords content><meta name=description content="Python异常处理（二十六）"><meta name=author content="极客快訊"><meta property="og:url" content="/cn/%E7%A7%91%E6%8A%80/b290700d.html"><link rel=apple-touch-icon sizes=180x180 href=../../apple-touch-icon.png><link rel=icon type=image/png sizes=32x32 href=../../favicon-32x32.png><link rel=icon type=image/png sizes=16x16 href=../../favicon-16x16.png><link rel=manifest href=../../site.webmanifest><link rel=mask-icon href=../../safari-pinned-tab.svg color=#5bbad5><meta name=msapplication-TileColor content="#ffc40d"><meta name=theme-color content="#ffffff"><link rel=stylesheet href=https://geekbank.cf/css/normalize.css><link rel=stylesheet href=https://geekbank.cf/css/style.css><script type=text/javascript src=https://cdnjs.cloudflare.com/ajax/libs/jquery/3.4.1/jquery.min.js></script><script type=text/javascript src=https://geekbank.cf/js/jqthumb.min.js></script><script data-ad-client=ca-pub-3525055026201463 async src=https://pagead2.googlesyndication.com/pagead/js/adsbygoogle.js></script></head><body><header id=header class=clearfix><div class=container><div class=col-group><div class=site-name><h1><a id=logo href>🤓 极客快讯 Geek Bank</a></h1><p class=description>为你带来最全的科技知识 🧡</p></div><div><nav id=nav-menu class=clearfix><a class=current href>猜你喜歡</a>
<a href=../../tw/categories/%E7%A7%91%E6%8A%80.html title=科技>科技</a>
<a href=../../tw/categories/%E9%81%8A%E6%88%B2.html title=遊戲>遊戲</a>
<a href=../../tw/categories/%E7%A7%91%E5%AD%B8.html title=科學>科學</a></nav></div></div></div></header><div id=body><div class=container><div class=col-group><div class=col-8 id=main><div class=res-cons><article class=post><header><h1 class=post-title>Python异常处理（二十六）</h1></header><date class="post-meta meta-date">2020-11-14</date><div class=post-meta><span>|</span>
<span class=meta-category><a href=cn/categories/%E7%A7%91%E6%8A%80.html>科技</a></span></div><div class=post-content><div><div class=pgc-img><img alt=Python异常处理（二十六） onerror=errorimg.call(this); src=https://p1.pstatp.com/large/pgc-image/b042ebd0bbf644a2b82bf1b115e79517><p class=pgc-img-caption></p></div><p>Python提供了两个非常重要的功能来处理Python程序中的异常和错误，并在其中添加调试的函数功能 -</p><ul><li>异常处理 - 在本教程中介绍。这是一个列表标准Python中提供的异常 - 标准异常。</li><li>断言 - 在<em>Python 3</em>教程中的断言中介绍。</li></ul><p>标准异常</p><p>以下是Python中可用的标准异常列表 -</p><div class=pgc-img><img alt=Python异常处理（二十六） onerror=errorimg.call(this); src=https://p1.pstatp.com/large/pgc-image/26d7ab6abae241c286a932c142c68231><p class=pgc-img-caption></p></div><p>Python中的断言</p><p>断言是一个健全检查，可以在完成对程序的测试后打开或关闭。</p><ul><li>试想断言的最简单的方法就是将它与一个raise-if语句(或者更准确的说是一个加注if语句)相对应。测试表达式，如果结果为false，则会引发异常。</li><li>断言由版本1.5引入的assert语句来执行，它是Python的最新关键字。</li><li>程序员经常在函数开始时放置断言来检查有效的输入，并在函数调用后检查有效的输出。</li></ul><p>assert语句</p><p>当它遇到一个assert语句时，Python会评估求值它的的表达式，是否为所希望的那样。 如果表达式为false，Python会引发AssertionError异常。</p><p>assert的语法是 -</p><pre>assert Expression[, Arguments]</pre><p>如果断言失败，Python将使用ArgumentExpression作为AssertionError的参数。 使用try-except语句可以像任何其他异常一样捕获和处理AssertionError异常。 如果没有处理，它们将终止程序并产生回溯。</p><p><strong>示例</strong></p><p>这里将实现一个功能：将给定的温度从开尔文转换为华氏度。如果是负温度，该功能将退出 -</p><pre>#!/usr/bin/python3def KelvinToFahrenheit(Temperature): assert (Temperature &gt;= 0),"Colder than absolute zero!" return ((Temperature-273)*1.8)+32print (KelvinToFahrenheit(273))print (int(KelvinToFahrenheit(505.78)))print (KelvinToFahrenheit(-5))</pre><p>当执行上述代码时，会产生以下结果 -</p><pre>32.0451Traceback (most recent call last):File "test.py", line 9, in &lt;module&gt;print KelvinToFahrenheit(-5)File "test.py", line 4, in KelvinToFahrenheitassert (Temperature &gt;= 0),"Colder than absolute zero!"AssertionError: Colder than absolute zero!</pre><p>什么是异常？</p><p>一个例外是在程序执行期间发生的一个事件，它破坏程序指令的正常流程。 一般来说，当Python脚本遇到无法应对的情况时，会引发异常。异常是一个表示错误的Python对象。</p><p>当Python脚本引发异常时，它必须立即处理异常，否则终止并退出。</p><p>处理异常</p><p>如果有一些可能引发异常的可疑代码，可以通过将可疑代码放在try:块中来保护您的程序。 在try:块之后，包括一个except:语句，然后是一个尽可能优雅地处理问题的代码块。</p><p><strong>语法</strong></p><p>下面是简单的语法try .... except ... else块 -</p><pre>try: You do your operations here ......................except ExceptionI: If there is ExceptionI, then execute this block.except ExceptionII: If there is ExceptionII, then execute this block. ......................else: If there is no exception then execute this block.</pre><p>以下是上述语法的几个重点 -</p><ul><li>一个try语句可以有多个except语句。 当try块包含可能引发不同类型的异常的语句时，这就很有用。</li><li>还可以提供一个通用的except子句，它处理任何异常。</li><li>在except子句之后，可以包含一个else子句。 如果try:block中的代码不引发异常，则else块中的代码将执行。</li><li>else-block是一个不需要try:block保护的代码的地方。</li></ul><p><strong>示例</strong></p><p>此示例打开一个文件，将内容写入文件，并且优雅地出现，因为完全没有问题 -</p><pre>#!/usr/bin/python3try: fh = open("testfile", "w") fh.write("This is my test file for exception handling!!")except IOError: print ("Error: can\'t find file or read data")else: print ("Written content in the file successfully") fh.close()</pre><p>这产生以下结果 -</p><pre>Written content in the file successfully</pre><p><strong>示例</strong></p><p>此示例尝试打开一个没有写入权限的文件，因此它引发了一个异常 -</p><pre>#!/usr/bin/python3try: fh = open("testfile", "r") fh.write("This is my test file for exception handling!!")except IOError: print ("Error: can\'t find file or read data")else: print ("Written content in the file successfully")</pre><p>这产生以下结果 -</p><pre>Error: can't find file or read data</pre><p>except子句没有指定异常</p><p>也可以使用except语句，但不定义异常，如下所示 -</p><pre>try: You do your operations here ......................except: If there is any exception, then execute this block. ......................else: If there is no exception then execute this block.</pre><p>这种try-except语句捕获所有发生的异常。使用这种try-except语句不被认为是一个很好的编程实践，因为它捕获所有异常，但不会让程序员能更好地识别发生的问题的根本原因。</p><p>except子句指定多个异常</p><p>还可以使用相同的except语句来处理多个异常，如下所示：</p><pre>try: You do your operations here ......................except(Exception1[, Exception2[,...ExceptionN]]]): If there is any exception from the given exception list,  then execute this block. ......................else: If there is no exception then execute this block.</pre><p>try-finally子句</p><p>可以使用finally：块和try：块。 finally：块是放置必须执行代码的地方，无论try块是否引发异常。 try-finally语句的语法是这样的 -</p><pre>try: You do your operations here; ...................... Due to any exception, this may be skipped.finally: This would always be executed. ......................</pre><blockquote><p>注意 - 可以提供except子句或finally子句，但不能同时提供。不能使用else子句以及finally子句。</p></blockquote><p><strong>示例</strong></p><pre>#!/usr/bin/python3try: fh = open("testfile", "w") fh.write("This is my test file for exception handling!!")finally: print ("Error: can\'t find file or read data") fh.close()</pre><p>如果没有以写入形式打开文件的权限，则会产生以下结果 -</p><pre>Error: can't find file or read data</pre><p>同样的例子可以写得更干净如下 -</p><pre>#!/usr/bin/python3try: fh = open("testfile", "w") try: fh.write("This is my test file for exception handling!!") finally: print ("Going to close the file") fh.close()except IOError: print ("Error: can\'t find file or read data")</pre><p>当try块中抛出异常时，执行将立即传递给finally块。 在finally块中的所有语句都被执行之后，异常被再次引发，如果存在于try-except语句的下一个更高的层中，则在except语句中处理异常。</p><p>异常参数</p><p>一个异常可以有一个参数，参数它是一个值，它提供有关该问题的其他信息。 参数的内容因异常而异。 可以通过在except子句中提供变量来捕获异常的参数，如下所示：</p><pre>try: You do your operations here ......................except ExceptionType as Argument: You can print value of Argument here...</pre><p>如果编写代码来处理单个异常，则可以在except语句中使用一个变量后跟异常的名称。 如果要捕获多个异常，可以使用一个变量后跟随异常的元组。</p><p>此变量接收大部分包含异常原因的异常值。 变量可以以元组的形式接收单个值或多个值。 该元组通常包含错误字符串，错误编号和错误位置。</p><p><strong>示例</strong></p><p>以下是一个例外 -</p><pre>#!/usr/bin/python3# Define a function here.def temp_convert(var): try: return int(var) except ValueError as Argument: print ("The argument does not contain numbers\n", Argument)# Call above function here.temp_convert("xyz")</pre><p>这产生以下结果 -</p><pre>The argument does not contain numbersinvalid literal for int() with base 10: 'xyz'</pre><p>抛出异常</p><p>可以通过使用raise语句以多种方式引发异常。raise语句的一般语法如下 -</p><p><strong>语法</strong></p><pre>raise [Exception [, args [, traceback]]]</pre><p>这里，Exception是异常的类型(例如，NameError)，args是异常参数的值。 参数是可选的; 如果没有提供，则异常参数为None。</p><p>最后一个参数traceback也是可选的(在实践中很少使用)，如果存在，则是用于异常的追溯对象。</p><p><strong>示例</strong></p><p>异常可以是字符串，类或对象。 Python核心引发的大多数异常都是类，一个参数是类的一个实例。 定义新的例外是非常容易的，可以做到如下 -</p><pre>def functionName( level ): if level &lt;1: raise Exception(level) # The code below to this would not be executed # if we raise the exception return level</pre><blockquote><p>注意 - 为了捕获异常，“except”子句必须引用与类对象或简单字符串相同的异常。例如，为了捕获上述异常，必须写出except子句如下：</p></blockquote><pre>try: Business Logic here...except Exception as e: Exception handling here using e.args...else: Rest of the code here...</pre><p>以下示例说明了使用引发异常 -</p><pre>#!/usr/bin/python3def functionName( level ): if level &lt;1: raise Exception(level) # The code below to this would not be executed # if we raise the exception return leveltry: l = functionName(-10) print ("level = ",l)except Exception as e: print ("error in level argument",e.args[0])</pre><p>这将产生以下结果 -</p><pre>error in level argument -10</pre><p>用户定义的异常</p><p>Python还允许通过从标准内置异常导出类来创建自己的异常。</p><p>这是一个与RuntimeError有关的示例。 在这里，从RuntimeError类创建一个子类。 当需要在捕获异常时显示更多具体信息时，这就很有用了。</p><p>在try块中，用户定义的异常被引发并被捕获在except块中。 变量e用于创建Networkerror类的实例。</p><pre>class Networkerror(RuntimeError): def __init__(self, arg): self.args = arg</pre><p>所以当定义了上面的类以后，就可以使用以下命令抛出异常 -</p><pre>try: raise Networkerror("Bad hostname")except Networkerror,e: print e.args</pre></div></div><div class="post-meta meta-tags"><ul class=clearfix><li><a>'Python','异常','处理'</a></li></ul></div></article></div></div><div id=secondary><section class=widget><form id=search action=//www.google.com/search method=get accept-charset=utf-8 target=_blank _lpchecked=1><input type=text name=q maxlength=20 placeholder=搜索>
<input type=hidden name=sitesearch value=geekbank.cf>
<button type=submit>🔍</button></form></section><section class=widget><h3 class=widget-title>最新文章 ⚡</h3><ul class=widget-list></ul></section><section class=widget><h3 class=widget-title>其他</h3><ul class=widget-list><li><a href=TOS.html>使用條款</a></li><li><a href=CommentPolicy.html>留言政策</a></li><li><a href=mailto:gdnews@tuta.io rel=nofollow>DMCA</a></li><li><a href=mailto:gdnews@tuta.io rel=nofollow>聯絡我們</a></li></ul></section></div></div></div></div><footer id=footer><div class=container>&copy; 2020 <a href>极客快訊</a></div></footer><script type=text/javascript>window.MathJax={tex2jax:{inlineMath:[['$','$']],processEscapes:true}};</script><script src="https://cdnjs.cloudflare.com/ajax/libs/mathjax/2.7.5/MathJax.js?config=TeX-MML-AM_CHTML" async></script><a id=rocket href=#top></a><script type=text/javascript src=https://kknews.cf/js/totop.js async></script><script type=application/javascript>var doNotTrack=false;if(!doNotTrack){window.ga=window.ga||function(){(ga.q=ga.q||[]).push(arguments)};ga.l=+new Date;ga('create','UA-146415161-2','auto');ga('send','pageview');}</script><script async src=https://www.google-analytics.com/analytics.js></script><script type=text/javascript src="//s7.addthis.com/js/300/addthis_widget.js#pubid=ra-5e508ed9e4e698bb"></script></body></html>